INFO:werkzeug: * Restarting with stat
INFO:werkzeug: * Running on http://0.0.0.0:5000/ (Press CTRL+C to quit)
ERROR:flask.app:Exception on / [GET]
Traceback (most recent call last):
  File "C:\Users\Developer_IVS\PycharmProjects\pyserver\venv\lib\site-packages\sqlalchemy\engine\base.py", line 2158, in _wrap_pool_connect
    return fn()
  File "C:\Users\Developer_IVS\PycharmProjects\pyserver\venv\lib\site-packages\sqlalchemy\pool.py", line 400, in connect
    return _ConnectionFairy._checkout(self)
  File "C:\Users\Developer_IVS\PycharmProjects\pyserver\venv\lib\site-packages\sqlalchemy\pool.py", line 788, in _checkout
    fairy = _ConnectionRecord.checkout(pool)
  File "C:\Users\Developer_IVS\PycharmProjects\pyserver\venv\lib\site-packages\sqlalchemy\pool.py", line 529, in checkout
    rec = pool._do_get()
  File "C:\Users\Developer_IVS\PycharmProjects\pyserver\venv\lib\site-packages\sqlalchemy\pool.py", line 1193, in _do_get
    self._dec_overflow()
  File "C:\Users\Developer_IVS\PycharmProjects\pyserver\venv\lib\site-packages\sqlalchemy\util\langhelpers.py", line 66, in __exit__
    compat.reraise(exc_type, exc_value, exc_tb)
  File "C:\Users\Developer_IVS\PycharmProjects\pyserver\venv\lib\site-packages\sqlalchemy\util\compat.py", line 249, in reraise
    raise value
  File "C:\Users\Developer_IVS\PycharmProjects\pyserver\venv\lib\site-packages\sqlalchemy\pool.py", line 1190, in _do_get
    return self._create_connection()
  File "C:\Users\Developer_IVS\PycharmProjects\pyserver\venv\lib\site-packages\sqlalchemy\pool.py", line 347, in _create_connection
    return _ConnectionRecord(self)
  File "C:\Users\Developer_IVS\PycharmProjects\pyserver\venv\lib\site-packages\sqlalchemy\pool.py", line 474, in __init__
    self.__connect(first_connect_check=True)
  File "C:\Users\Developer_IVS\PycharmProjects\pyserver\venv\lib\site-packages\sqlalchemy\pool.py", line 671, in __connect
    connection = pool._invoke_creator(self)
  File "C:\Users\Developer_IVS\PycharmProjects\pyserver\venv\lib\site-packages\sqlalchemy\engine\strategies.py", line 106, in connect
    return dialect.connect(*cargs, **cparams)
  File "C:\Users\Developer_IVS\PycharmProjects\pyserver\venv\lib\site-packages\sqlalchemy\engine\default.py", line 412, in connect
    return self.dbapi.connect(*cargs, **cparams)
  File "C:\Users\Developer_IVS\PycharmProjects\pyserver\venv\lib\site-packages\psycopg2\__init__.py", line 130, in connect
    conn = _connect(dsn, connection_factory=connection_factory, **kwasync)
psycopg2.OperationalError: could not translate host name "db" to address: Unknown host


The above exception was the direct cause of the following exception:

Traceback (most recent call last):
  File "C:\Users\Developer_IVS\PycharmProjects\pyserver\venv\lib\site-packages\flask\app.py", line 2292, in wsgi_app
    response = self.full_dispatch_request()
  File "C:\Users\Developer_IVS\PycharmProjects\pyserver\venv\lib\site-packages\flask\app.py", line 1808, in full_dispatch_request
    self.try_trigger_before_first_request_functions()
  File "C:\Users\Developer_IVS\PycharmProjects\pyserver\venv\lib\site-packages\flask\app.py", line 1855, in try_trigger_before_first_request_functions
    func()
  File "C:\Users\Developer_IVS\Downloads\flask-gentelella-master\flask-gentelella-master\app\__init__.py", line 26, in initialize_database
    db.create_all()
  File "C:\Users\Developer_IVS\PycharmProjects\pyserver\venv\lib\site-packages\flask_sqlalchemy\__init__.py", line 963, in create_all
    self._execute_for_all_tables(app, bind, 'create_all')
  File "C:\Users\Developer_IVS\PycharmProjects\pyserver\venv\lib\site-packages\flask_sqlalchemy\__init__.py", line 955, in _execute_for_all_tables
    op(bind=self.get_engine(app, bind), **extra)
  File "C:\Users\Developer_IVS\PycharmProjects\pyserver\venv\lib\site-packages\sqlalchemy\sql\schema.py", line 4005, in create_all
    tables=tables)
  File "C:\Users\Developer_IVS\PycharmProjects\pyserver\venv\lib\site-packages\sqlalchemy\engine\base.py", line 1939, in _run_visitor
    with self._optional_conn_ctx_manager(connection) as conn:
  File "C:\Users\Developer_IVS\AppData\Local\Programs\Python\Python37-32\lib\contextlib.py", line 112, in __enter__
    return next(self.gen)
  File "C:\Users\Developer_IVS\PycharmProjects\pyserver\venv\lib\site-packages\sqlalchemy\engine\base.py", line 1932, in _optional_conn_ctx_manager
    with self.contextual_connect() as conn:
  File "C:\Users\Developer_IVS\PycharmProjects\pyserver\venv\lib\site-packages\sqlalchemy\engine\base.py", line 2123, in contextual_connect
    self._wrap_pool_connect(self.pool.connect, None),
  File "C:\Users\Developer_IVS\PycharmProjects\pyserver\venv\lib\site-packages\sqlalchemy\engine\base.py", line 2162, in _wrap_pool_connect
    e, dialect, self)
  File "C:\Users\Developer_IVS\PycharmProjects\pyserver\venv\lib\site-packages\sqlalchemy\engine\base.py", line 1476, in _handle_dbapi_exception_noconnection
    exc_info
  File "C:\Users\Developer_IVS\PycharmProjects\pyserver\venv\lib\site-packages\sqlalchemy\util\compat.py", line 265, in raise_from_cause
    reraise(type(exception), exception, tb=exc_tb, cause=cause)
  File "C:\Users\Developer_IVS\PycharmProjects\pyserver\venv\lib\site-packages\sqlalchemy\util\compat.py", line 248, in reraise
    raise value.with_traceback(tb)
  File "C:\Users\Developer_IVS\PycharmProjects\pyserver\venv\lib\site-packages\sqlalchemy\engine\base.py", line 2158, in _wrap_pool_connect
    return fn()
  File "C:\Users\Developer_IVS\PycharmProjects\pyserver\venv\lib\site-packages\sqlalchemy\pool.py", line 400, in connect
    return _ConnectionFairy._checkout(self)
  File "C:\Users\Developer_IVS\PycharmProjects\pyserver\venv\lib\site-packages\sqlalchemy\pool.py", line 788, in _checkout
    fairy = _ConnectionRecord.checkout(pool)
  File "C:\Users\Developer_IVS\PycharmProjects\pyserver\venv\lib\site-packages\sqlalchemy\pool.py", line 529, in checkout
    rec = pool._do_get()
  File "C:\Users\Developer_IVS\PycharmProjects\pyserver\venv\lib\site-packages\sqlalchemy\pool.py", line 1193, in _do_get
    self._dec_overflow()
  File "C:\Users\Developer_IVS\PycharmProjects\pyserver\venv\lib\site-packages\sqlalchemy\util\langhelpers.py", line 66, in __exit__
    compat.reraise(exc_type, exc_value, exc_tb)
  File "C:\Users\Developer_IVS\PycharmProjects\pyserver\venv\lib\site-packages\sqlalchemy\util\compat.py", line 249, in reraise
    raise value
  File "C:\Users\Developer_IVS\PycharmProjects\pyserver\venv\lib\site-packages\sqlalchemy\pool.py", line 1190, in _do_get
    return self._create_connection()
  File "C:\Users\Developer_IVS\PycharmProjects\pyserver\venv\lib\site-packages\sqlalchemy\pool.py", line 347, in _create_connection
    return _ConnectionRecord(self)
  File "C:\Users\Developer_IVS\PycharmProjects\pyserver\venv\lib\site-packages\sqlalchemy\pool.py", line 474, in __init__
    self.__connect(first_connect_check=True)
  File "C:\Users\Developer_IVS\PycharmProjects\pyserver\venv\lib\site-packages\sqlalchemy\pool.py", line 671, in __connect
    connection = pool._invoke_creator(self)
  File "C:\Users\Developer_IVS\PycharmProjects\pyserver\venv\lib\site-packages\sqlalchemy\engine\strategies.py", line 106, in connect
    return dialect.connect(*cargs, **cparams)
  File "C:\Users\Developer_IVS\PycharmProjects\pyserver\venv\lib\site-packages\sqlalchemy\engine\default.py", line 412, in connect
    return self.dbapi.connect(*cargs, **cparams)
  File "C:\Users\Developer_IVS\PycharmProjects\pyserver\venv\lib\site-packages\psycopg2\__init__.py", line 130, in connect
    conn = _connect(dsn, connection_factory=connection_factory, **kwasync)
sqlalchemy.exc.OperationalError: (psycopg2.OperationalError) could not translate host name "db" to address: Unknown host
 (Background on this error at: http://sqlalche.me/e/e3q8)
INFO:werkzeug:217.15.192.13 - - [09/Nov/2018 17:42:02] "GET / HTTP/1.1" 500 -
ERROR:werkzeug:Error on request:
Traceback (most recent call last):
  File "C:\Users\Developer_IVS\PycharmProjects\pyserver\venv\lib\site-packages\werkzeug\serving.py", line 270, in run_wsgi
    execute(self.server.app)
  File "C:\Users\Developer_IVS\PycharmProjects\pyserver\venv\lib\site-packages\werkzeug\serving.py", line 258, in execute
    application_iter = app(environ, start_response)
  File "C:\Users\Developer_IVS\PycharmProjects\pyserver\venv\lib\site-packages\flask\app.py", line 2309, in __call__
    return self.wsgi_app(environ, start_response)
  File "C:\Users\Developer_IVS\PycharmProjects\pyserver\venv\lib\site-packages\flask\app.py", line 2295, in wsgi_app
    response = self.handle_exception(e)
  File "C:\Users\Developer_IVS\PycharmProjects\pyserver\venv\lib\site-packages\flask\app.py", line 1748, in handle_exception
    return self.finalize_request(handler(e), from_error_handler=True)
  File "C:\Users\Developer_IVS\Downloads\flask-gentelella-master\flask-gentelella-master\app\base\routes.py", line 102, in internal_error
    return render_template('errors/page_500.html'), 500
  File "C:\Users\Developer_IVS\PycharmProjects\pyserver\venv\lib\site-packages\flask\templating.py", line 133, in render_template
    ctx.app.update_template_context(context)
  File "C:\Users\Developer_IVS\PycharmProjects\pyserver\venv\lib\site-packages\flask\app.py", line 792, in update_template_context
    context.update(func())
  File "C:\Users\Developer_IVS\PycharmProjects\pyserver\venv\lib\site-packages\flask_login\utils.py", line 368, in _user_context_processor
    return dict(current_user=_get_user())
  File "C:\Users\Developer_IVS\PycharmProjects\pyserver\venv\lib\site-packages\flask_login\utils.py", line 335, in _get_user
    current_app.login_manager._load_user()
  File "C:\Users\Developer_IVS\PycharmProjects\pyserver\venv\lib\site-packages\flask_login\login_manager.py", line 355, in _load_user
    return self._load_from_request(request)
  File "C:\Users\Developer_IVS\PycharmProjects\pyserver\venv\lib\site-packages\flask_login\login_manager.py", line 412, in _load_from_request
    user = self.request_callback(request)
  File "C:\Users\Developer_IVS\Downloads\flask-gentelella-master\flask-gentelella-master\app\base\models.py", line 219, in request_loader
    user = User.query.filter_by(username=username).first()
  File "C:\Users\Developer_IVS\PycharmProjects\pyserver\venv\lib\site-packages\sqlalchemy\orm\query.py", line 2895, in first
    ret = list(self[0:1])
  File "C:\Users\Developer_IVS\PycharmProjects\pyserver\venv\lib\site-packages\sqlalchemy\orm\query.py", line 2687, in __getitem__
    return list(res)
  File "C:\Users\Developer_IVS\PycharmProjects\pyserver\venv\lib\site-packages\sqlalchemy\orm\query.py", line 2995, in __iter__
    return self._execute_and_instances(context)
  File "C:\Users\Developer_IVS\PycharmProjects\pyserver\venv\lib\site-packages\sqlalchemy\orm\query.py", line 3016, in _execute_and_instances
    close_with_result=True)
  File "C:\Users\Developer_IVS\PycharmProjects\pyserver\venv\lib\site-packages\sqlalchemy\orm\query.py", line 3025, in _get_bind_args
    **kw
  File "C:\Users\Developer_IVS\PycharmProjects\pyserver\venv\lib\site-packages\sqlalchemy\orm\query.py", line 3007, in _connection_from_session
    conn = self.session.connection(**kw)
  File "C:\Users\Developer_IVS\PycharmProjects\pyserver\venv\lib\site-packages\sqlalchemy\orm\session.py", line 1035, in connection
    execution_options=execution_options)
  File "C:\Users\Developer_IVS\PycharmProjects\pyserver\venv\lib\site-packages\sqlalchemy\orm\session.py", line 1040, in _connection_for_bind
    engine, execution_options)
  File "C:\Users\Developer_IVS\PycharmProjects\pyserver\venv\lib\site-packages\sqlalchemy\orm\session.py", line 409, in _connection_for_bind
    conn = bind.contextual_connect()
  File "C:\Users\Developer_IVS\PycharmProjects\pyserver\venv\lib\site-packages\sqlalchemy\engine\base.py", line 2123, in contextual_connect
    self._wrap_pool_connect(self.pool.connect, None),
  File "C:\Users\Developer_IVS\PycharmProjects\pyserver\venv\lib\site-packages\sqlalchemy\engine\base.py", line 2162, in _wrap_pool_connect
    e, dialect, self)
  File "C:\Users\Developer_IVS\PycharmProjects\pyserver\venv\lib\site-packages\sqlalchemy\engine\base.py", line 1476, in _handle_dbapi_exception_noconnection
    exc_info
  File "C:\Users\Developer_IVS\PycharmProjects\pyserver\venv\lib\site-packages\sqlalchemy\util\compat.py", line 265, in raise_from_cause
    reraise(type(exception), exception, tb=exc_tb, cause=cause)
  File "C:\Users\Developer_IVS\PycharmProjects\pyserver\venv\lib\site-packages\sqlalchemy\util\compat.py", line 248, in reraise
    raise value.with_traceback(tb)
  File "C:\Users\Developer_IVS\PycharmProjects\pyserver\venv\lib\site-packages\sqlalchemy\engine\base.py", line 2158, in _wrap_pool_connect
    return fn()
  File "C:\Users\Developer_IVS\PycharmProjects\pyserver\venv\lib\site-packages\sqlalchemy\pool.py", line 400, in connect
    return _ConnectionFairy._checkout(self)
  File "C:\Users\Developer_IVS\PycharmProjects\pyserver\venv\lib\site-packages\sqlalchemy\pool.py", line 788, in _checkout
    fairy = _ConnectionRecord.checkout(pool)
  File "C:\Users\Developer_IVS\PycharmProjects\pyserver\venv\lib\site-packages\sqlalchemy\pool.py", line 529, in checkout
    rec = pool._do_get()
  File "C:\Users\Developer_IVS\PycharmProjects\pyserver\venv\lib\site-packages\sqlalchemy\pool.py", line 1193, in _do_get
    self._dec_overflow()
  File "C:\Users\Developer_IVS\PycharmProjects\pyserver\venv\lib\site-packages\sqlalchemy\util\langhelpers.py", line 66, in __exit__
    compat.reraise(exc_type, exc_value, exc_tb)
  File "C:\Users\Developer_IVS\PycharmProjects\pyserver\venv\lib\site-packages\sqlalchemy\util\compat.py", line 249, in reraise
    raise value
  File "C:\Users\Developer_IVS\PycharmProjects\pyserver\venv\lib\site-packages\sqlalchemy\pool.py", line 1190, in _do_get
    return self._create_connection()
  File "C:\Users\Developer_IVS\PycharmProjects\pyserver\venv\lib\site-packages\sqlalchemy\pool.py", line 347, in _create_connection
    return _ConnectionRecord(self)
  File "C:\Users\Developer_IVS\PycharmProjects\pyserver\venv\lib\site-packages\sqlalchemy\pool.py", line 474, in __init__
    self.__connect(first_connect_check=True)
  File "C:\Users\Developer_IVS\PycharmProjects\pyserver\venv\lib\site-packages\sqlalchemy\pool.py", line 671, in __connect
    connection = pool._invoke_creator(self)
  File "C:\Users\Developer_IVS\PycharmProjects\pyserver\venv\lib\site-packages\sqlalchemy\engine\strategies.py", line 106, in connect
    return dialect.connect(*cargs, **cparams)
  File "C:\Users\Developer_IVS\PycharmProjects\pyserver\venv\lib\site-packages\sqlalchemy\engine\default.py", line 412, in connect
    return self.dbapi.connect(*cargs, **cparams)
  File "C:\Users\Developer_IVS\PycharmProjects\pyserver\venv\lib\site-packages\psycopg2\__init__.py", line 130, in connect
    conn = _connect(dsn, connection_factory=connection_factory, **kwasync)
sqlalchemy.exc.OperationalError: (psycopg2.OperationalError) could not translate host name "db" to address: Unknown host
 (Background on this error at: http://sqlalche.me/e/e3q8)
ERROR:flask.app:Exception on /favicon.ico [GET]
Traceback (most recent call last):
  File "C:\Users\Developer_IVS\PycharmProjects\pyserver\venv\lib\site-packages\sqlalchemy\engine\base.py", line 2158, in _wrap_pool_connect
    return fn()
  File "C:\Users\Developer_IVS\PycharmProjects\pyserver\venv\lib\site-packages\sqlalchemy\pool.py", line 400, in connect
    return _ConnectionFairy._checkout(self)
  File "C:\Users\Developer_IVS\PycharmProjects\pyserver\venv\lib\site-packages\sqlalchemy\pool.py", line 788, in _checkout
    fairy = _ConnectionRecord.checkout(pool)
  File "C:\Users\Developer_IVS\PycharmProjects\pyserver\venv\lib\site-packages\sqlalchemy\pool.py", line 529, in checkout
    rec = pool._do_get()
  File "C:\Users\Developer_IVS\PycharmProjects\pyserver\venv\lib\site-packages\sqlalchemy\pool.py", line 1193, in _do_get
    self._dec_overflow()
  File "C:\Users\Developer_IVS\PycharmProjects\pyserver\venv\lib\site-packages\sqlalchemy\util\langhelpers.py", line 66, in __exit__
    compat.reraise(exc_type, exc_value, exc_tb)
  File "C:\Users\Developer_IVS\PycharmProjects\pyserver\venv\lib\site-packages\sqlalchemy\util\compat.py", line 249, in reraise
    raise value
  File "C:\Users\Developer_IVS\PycharmProjects\pyserver\venv\lib\site-packages\sqlalchemy\pool.py", line 1190, in _do_get
    return self._create_connection()
  File "C:\Users\Developer_IVS\PycharmProjects\pyserver\venv\lib\site-packages\sqlalchemy\pool.py", line 347, in _create_connection
    return _ConnectionRecord(self)
  File "C:\Users\Developer_IVS\PycharmProjects\pyserver\venv\lib\site-packages\sqlalchemy\pool.py", line 474, in __init__
    self.__connect(first_connect_check=True)
  File "C:\Users\Developer_IVS\PycharmProjects\pyserver\venv\lib\site-packages\sqlalchemy\pool.py", line 671, in __connect
    connection = pool._invoke_creator(self)
  File "C:\Users\Developer_IVS\PycharmProjects\pyserver\venv\lib\site-packages\sqlalchemy\engine\strategies.py", line 106, in connect
    return dialect.connect(*cargs, **cparams)
  File "C:\Users\Developer_IVS\PycharmProjects\pyserver\venv\lib\site-packages\sqlalchemy\engine\default.py", line 412, in connect
    return self.dbapi.connect(*cargs, **cparams)
  File "C:\Users\Developer_IVS\PycharmProjects\pyserver\venv\lib\site-packages\psycopg2\__init__.py", line 130, in connect
    conn = _connect(dsn, connection_factory=connection_factory, **kwasync)
psycopg2.OperationalError: could not translate host name "db" to address: Unknown host


The above exception was the direct cause of the following exception:

Traceback (most recent call last):
  File "C:\Users\Developer_IVS\PycharmProjects\pyserver\venv\lib\site-packages\flask\app.py", line 2292, in wsgi_app
    response = self.full_dispatch_request()
  File "C:\Users\Developer_IVS\PycharmProjects\pyserver\venv\lib\site-packages\flask\app.py", line 1808, in full_dispatch_request
    self.try_trigger_before_first_request_functions()
  File "C:\Users\Developer_IVS\PycharmProjects\pyserver\venv\lib\site-packages\flask\app.py", line 1855, in try_trigger_before_first_request_functions
    func()
  File "C:\Users\Developer_IVS\Downloads\flask-gentelella-master\flask-gentelella-master\app\__init__.py", line 26, in initialize_database
    db.create_all()
  File "C:\Users\Developer_IVS\PycharmProjects\pyserver\venv\lib\site-packages\flask_sqlalchemy\__init__.py", line 963, in create_all
    self._execute_for_all_tables(app, bind, 'create_all')
  File "C:\Users\Developer_IVS\PycharmProjects\pyserver\venv\lib\site-packages\flask_sqlalchemy\__init__.py", line 955, in _execute_for_all_tables
    op(bind=self.get_engine(app, bind), **extra)
  File "C:\Users\Developer_IVS\PycharmProjects\pyserver\venv\lib\site-packages\sqlalchemy\sql\schema.py", line 4005, in create_all
    tables=tables)
  File "C:\Users\Developer_IVS\PycharmProjects\pyserver\venv\lib\site-packages\sqlalchemy\engine\base.py", line 1939, in _run_visitor
    with self._optional_conn_ctx_manager(connection) as conn:
  File "C:\Users\Developer_IVS\AppData\Local\Programs\Python\Python37-32\lib\contextlib.py", line 112, in __enter__
    return next(self.gen)
  File "C:\Users\Developer_IVS\PycharmProjects\pyserver\venv\lib\site-packages\sqlalchemy\engine\base.py", line 1932, in _optional_conn_ctx_manager
    with self.contextual_connect() as conn:
  File "C:\Users\Developer_IVS\PycharmProjects\pyserver\venv\lib\site-packages\sqlalchemy\engine\base.py", line 2123, in contextual_connect
    self._wrap_pool_connect(self.pool.connect, None),
  File "C:\Users\Developer_IVS\PycharmProjects\pyserver\venv\lib\site-packages\sqlalchemy\engine\base.py", line 2162, in _wrap_pool_connect
    e, dialect, self)
  File "C:\Users\Developer_IVS\PycharmProjects\pyserver\venv\lib\site-packages\sqlalchemy\engine\base.py", line 1476, in _handle_dbapi_exception_noconnection
    exc_info
  File "C:\Users\Developer_IVS\PycharmProjects\pyserver\venv\lib\site-packages\sqlalchemy\util\compat.py", line 265, in raise_from_cause
    reraise(type(exception), exception, tb=exc_tb, cause=cause)
  File "C:\Users\Developer_IVS\PycharmProjects\pyserver\venv\lib\site-packages\sqlalchemy\util\compat.py", line 248, in reraise
    raise value.with_traceback(tb)
  File "C:\Users\Developer_IVS\PycharmProjects\pyserver\venv\lib\site-packages\sqlalchemy\engine\base.py", line 2158, in _wrap_pool_connect
    return fn()
  File "C:\Users\Developer_IVS\PycharmProjects\pyserver\venv\lib\site-packages\sqlalchemy\pool.py", line 400, in connect
    return _ConnectionFairy._checkout(self)
  File "C:\Users\Developer_IVS\PycharmProjects\pyserver\venv\lib\site-packages\sqlalchemy\pool.py", line 788, in _checkout
    fairy = _ConnectionRecord.checkout(pool)
  File "C:\Users\Developer_IVS\PycharmProjects\pyserver\venv\lib\site-packages\sqlalchemy\pool.py", line 529, in checkout
    rec = pool._do_get()
  File "C:\Users\Developer_IVS\PycharmProjects\pyserver\venv\lib\site-packages\sqlalchemy\pool.py", line 1193, in _do_get
    self._dec_overflow()
  File "C:\Users\Developer_IVS\PycharmProjects\pyserver\venv\lib\site-packages\sqlalchemy\util\langhelpers.py", line 66, in __exit__
    compat.reraise(exc_type, exc_value, exc_tb)
  File "C:\Users\Developer_IVS\PycharmProjects\pyserver\venv\lib\site-packages\sqlalchemy\util\compat.py", line 249, in reraise
    raise value
  File "C:\Users\Developer_IVS\PycharmProjects\pyserver\venv\lib\site-packages\sqlalchemy\pool.py", line 1190, in _do_get
    return self._create_connection()
  File "C:\Users\Developer_IVS\PycharmProjects\pyserver\venv\lib\site-packages\sqlalchemy\pool.py", line 347, in _create_connection
    return _ConnectionRecord(self)
  File "C:\Users\Developer_IVS\PycharmProjects\pyserver\venv\lib\site-packages\sqlalchemy\pool.py", line 474, in __init__
    self.__connect(first_connect_check=True)
  File "C:\Users\Developer_IVS\PycharmProjects\pyserver\venv\lib\site-packages\sqlalchemy\pool.py", line 671, in __connect
    connection = pool._invoke_creator(self)
  File "C:\Users\Developer_IVS\PycharmProjects\pyserver\venv\lib\site-packages\sqlalchemy\engine\strategies.py", line 106, in connect
    return dialect.connect(*cargs, **cparams)
  File "C:\Users\Developer_IVS\PycharmProjects\pyserver\venv\lib\site-packages\sqlalchemy\engine\default.py", line 412, in connect
    return self.dbapi.connect(*cargs, **cparams)
  File "C:\Users\Developer_IVS\PycharmProjects\pyserver\venv\lib\site-packages\psycopg2\__init__.py", line 130, in connect
    conn = _connect(dsn, connection_factory=connection_factory, **kwasync)
sqlalchemy.exc.OperationalError: (psycopg2.OperationalError) could not translate host name "db" to address: Unknown host
 (Background on this error at: http://sqlalche.me/e/e3q8)
INFO:werkzeug:217.15.192.13 - - [09/Nov/2018 17:42:06] "GET /favicon.ico HTTP/1.1" 500 -
ERROR:werkzeug:Error on request:
Traceback (most recent call last):
  File "C:\Users\Developer_IVS\PycharmProjects\pyserver\venv\lib\site-packages\werkzeug\serving.py", line 270, in run_wsgi
    execute(self.server.app)
  File "C:\Users\Developer_IVS\PycharmProjects\pyserver\venv\lib\site-packages\werkzeug\serving.py", line 258, in execute
    application_iter = app(environ, start_response)
  File "C:\Users\Developer_IVS\PycharmProjects\pyserver\venv\lib\site-packages\flask\app.py", line 2309, in __call__
    return self.wsgi_app(environ, start_response)
  File "C:\Users\Developer_IVS\PycharmProjects\pyserver\venv\lib\site-packages\flask\app.py", line 2295, in wsgi_app
    response = self.handle_exception(e)
  File "C:\Users\Developer_IVS\PycharmProjects\pyserver\venv\lib\site-packages\flask\app.py", line 1748, in handle_exception
    return self.finalize_request(handler(e), from_error_handler=True)
  File "C:\Users\Developer_IVS\Downloads\flask-gentelella-master\flask-gentelella-master\app\base\routes.py", line 102, in internal_error
    return render_template('errors/page_500.html'), 500
  File "C:\Users\Developer_IVS\PycharmProjects\pyserver\venv\lib\site-packages\flask\templating.py", line 133, in render_template
    ctx.app.update_template_context(context)
  File "C:\Users\Developer_IVS\PycharmProjects\pyserver\venv\lib\site-packages\flask\app.py", line 792, in update_template_context
    context.update(func())
  File "C:\Users\Developer_IVS\PycharmProjects\pyserver\venv\lib\site-packages\flask_login\utils.py", line 368, in _user_context_processor
    return dict(current_user=_get_user())
  File "C:\Users\Developer_IVS\PycharmProjects\pyserver\venv\lib\site-packages\flask_login\utils.py", line 335, in _get_user
    current_app.login_manager._load_user()
  File "C:\Users\Developer_IVS\PycharmProjects\pyserver\venv\lib\site-packages\flask_login\login_manager.py", line 355, in _load_user
    return self._load_from_request(request)
  File "C:\Users\Developer_IVS\PycharmProjects\pyserver\venv\lib\site-packages\flask_login\login_manager.py", line 412, in _load_from_request
    user = self.request_callback(request)
  File "C:\Users\Developer_IVS\Downloads\flask-gentelella-master\flask-gentelella-master\app\base\models.py", line 219, in request_loader
    user = User.query.filter_by(username=username).first()
  File "C:\Users\Developer_IVS\PycharmProjects\pyserver\venv\lib\site-packages\sqlalchemy\orm\query.py", line 2895, in first
    ret = list(self[0:1])
  File "C:\Users\Developer_IVS\PycharmProjects\pyserver\venv\lib\site-packages\sqlalchemy\orm\query.py", line 2687, in __getitem__
    return list(res)
  File "C:\Users\Developer_IVS\PycharmProjects\pyserver\venv\lib\site-packages\sqlalchemy\orm\query.py", line 2995, in __iter__
    return self._execute_and_instances(context)
  File "C:\Users\Developer_IVS\PycharmProjects\pyserver\venv\lib\site-packages\sqlalchemy\orm\query.py", line 3016, in _execute_and_instances
    close_with_result=True)
  File "C:\Users\Developer_IVS\PycharmProjects\pyserver\venv\lib\site-packages\sqlalchemy\orm\query.py", line 3025, in _get_bind_args
    **kw
  File "C:\Users\Developer_IVS\PycharmProjects\pyserver\venv\lib\site-packages\sqlalchemy\orm\query.py", line 3007, in _connection_from_session
    conn = self.session.connection(**kw)
  File "C:\Users\Developer_IVS\PycharmProjects\pyserver\venv\lib\site-packages\sqlalchemy\orm\session.py", line 1035, in connection
    execution_options=execution_options)
  File "C:\Users\Developer_IVS\PycharmProjects\pyserver\venv\lib\site-packages\sqlalchemy\orm\session.py", line 1040, in _connection_for_bind
    engine, execution_options)
  File "C:\Users\Developer_IVS\PycharmProjects\pyserver\venv\lib\site-packages\sqlalchemy\orm\session.py", line 409, in _connection_for_bind
    conn = bind.contextual_connect()
  File "C:\Users\Developer_IVS\PycharmProjects\pyserver\venv\lib\site-packages\sqlalchemy\engine\base.py", line 2123, in contextual_connect
    self._wrap_pool_connect(self.pool.connect, None),
  File "C:\Users\Developer_IVS\PycharmProjects\pyserver\venv\lib\site-packages\sqlalchemy\engine\base.py", line 2162, in _wrap_pool_connect
    e, dialect, self)
  File "C:\Users\Developer_IVS\PycharmProjects\pyserver\venv\lib\site-packages\sqlalchemy\engine\base.py", line 1476, in _handle_dbapi_exception_noconnection
    exc_info
  File "C:\Users\Developer_IVS\PycharmProjects\pyserver\venv\lib\site-packages\sqlalchemy\util\compat.py", line 265, in raise_from_cause
    reraise(type(exception), exception, tb=exc_tb, cause=cause)
  File "C:\Users\Developer_IVS\PycharmProjects\pyserver\venv\lib\site-packages\sqlalchemy\util\compat.py", line 248, in reraise
    raise value.with_traceback(tb)
  File "C:\Users\Developer_IVS\PycharmProjects\pyserver\venv\lib\site-packages\sqlalchemy\engine\base.py", line 2158, in _wrap_pool_connect
    return fn()
  File "C:\Users\Developer_IVS\PycharmProjects\pyserver\venv\lib\site-packages\sqlalchemy\pool.py", line 400, in connect
    return _ConnectionFairy._checkout(self)
  File "C:\Users\Developer_IVS\PycharmProjects\pyserver\venv\lib\site-packages\sqlalchemy\pool.py", line 788, in _checkout
    fairy = _ConnectionRecord.checkout(pool)
  File "C:\Users\Developer_IVS\PycharmProjects\pyserver\venv\lib\site-packages\sqlalchemy\pool.py", line 529, in checkout
    rec = pool._do_get()
  File "C:\Users\Developer_IVS\PycharmProjects\pyserver\venv\lib\site-packages\sqlalchemy\pool.py", line 1193, in _do_get
    self._dec_overflow()
  File "C:\Users\Developer_IVS\PycharmProjects\pyserver\venv\lib\site-packages\sqlalchemy\util\langhelpers.py", line 66, in __exit__
    compat.reraise(exc_type, exc_value, exc_tb)
  File "C:\Users\Developer_IVS\PycharmProjects\pyserver\venv\lib\site-packages\sqlalchemy\util\compat.py", line 249, in reraise
    raise value
  File "C:\Users\Developer_IVS\PycharmProjects\pyserver\venv\lib\site-packages\sqlalchemy\pool.py", line 1190, in _do_get
    return self._create_connection()
  File "C:\Users\Developer_IVS\PycharmProjects\pyserver\venv\lib\site-packages\sqlalchemy\pool.py", line 347, in _create_connection
    return _ConnectionRecord(self)
  File "C:\Users\Developer_IVS\PycharmProjects\pyserver\venv\lib\site-packages\sqlalchemy\pool.py", line 474, in __init__
    self.__connect(first_connect_check=True)
  File "C:\Users\Developer_IVS\PycharmProjects\pyserver\venv\lib\site-packages\sqlalchemy\pool.py", line 671, in __connect
    connection = pool._invoke_creator(self)
  File "C:\Users\Developer_IVS\PycharmProjects\pyserver\venv\lib\site-packages\sqlalchemy\engine\strategies.py", line 106, in connect
    return dialect.connect(*cargs, **cparams)
  File "C:\Users\Developer_IVS\PycharmProjects\pyserver\venv\lib\site-packages\sqlalchemy\engine\default.py", line 412, in connect
    return self.dbapi.connect(*cargs, **cparams)
  File "C:\Users\Developer_IVS\PycharmProjects\pyserver\venv\lib\site-packages\psycopg2\__init__.py", line 130, in connect
    conn = _connect(dsn, connection_factory=connection_factory, **kwasync)
sqlalchemy.exc.OperationalError: (psycopg2.OperationalError) could not translate host name "db" to address: Unknown host
 (Background on this error at: http://sqlalche.me/e/e3q8)
